<sdf version='1.7'>
  <world name='default'>
    <gui fullscreen='0'>
      <camera name='user_camera'>
        <pose>12.9141 -52.2347 1.94342 0 0.279993 1.6605</pose>
        <view_controller>orbit</view_controller>
        <projection_type>perspective</projection_type>
      </camera>
      <plugin name='keyboard' filename='libKeyboardGUIPlugin.so'/>
    </gui>
    <physics name='default_physics' default='0' type='ode'>
      <ode>
        <solver>
          <type>quick</type>
          <iters>100</iters>
          <sor>1</sor>
          <use_dynamic_moi_rescaling>0</use_dynamic_moi_rescaling>
        </solver>
        <constraints>
          <cfm>0</cfm>
          <erp>0.2</erp>
          <contact_max_correcting_vel>0.1</contact_max_correcting_vel>
          <contact_surface_layer>0</contact_surface_layer>
        </constraints>
      </ode>
      <real_time_factor>1</real_time_factor>
      <max_step_size>0.001</max_step_size>
      <real_time_update_rate>1000</real_time_update_rate>
    </physics>
    <scene>
      <sky>
        <clouds>
          <speed>5</speed>
        </clouds>
      </sky>
      <ambient>0.95 0.95 0.95 1</ambient>
      <background>0.3 0.3 0.3 1</background>
      <shadows>1</shadows>
    </scene>
    <gravity>0 0 -9.8</gravity>
    <magnetic_field>6e-06 2.3e-05 -4.2e-05</magnetic_field>
    <atmosphere type='adiabatic'/>
    <audio>
      <device>default</device>
    </audio>
    <wind/>
    <spherical_coordinates>
      <surface_model>EARTH_WGS84</surface_model>
      <latitude_deg>0</latitude_deg>
      <longitude_deg>0</longitude_deg>
      <elevation>0</elevation>
      <heading_deg>0</heading_deg>
    </spherical_coordinates>
    <state world_name='default'>
      <sim_time>5816 607000000</sim_time>
      <real_time>18 445624172</real_time>
      <wall_time>1647293827 91831346</wall_time>
      <iterations>17667</iterations>
      <model name='alan'>
        <pose>11.5446 -0.896078 -0.088418 0 -0 0</pose>
        <scale>1 1 1</scale>
        <link name='link'>
          <pose>11.5446 -0.896078 -0.088418 0 -0 0</pose>
          <velocity>0 0 0 0 -0 0</velocity>
          <acceleration>0 0 0 0 -0 0</acceleration>
          <wrench>0 0 0 0 -0 0</wrench>
        </link>
      </model>
      <model name='daire'>
        <pose>9.38504 49.0598 0.027299 0 -0 0</pose>
        <scale>1 1 1</scale>
        <link name='link'>
          <pose>9.38504 49.0598 0.027299 0 -0 0</pose>
          <velocity>0 0 0 0 -0 0</velocity>
          <acceleration>0 0 0 0 -0 0</acceleration>
          <wrench>0 0 0 0 -0 0</wrench>
        </link>
      </model>
      <model name='ground_plane'>
        <pose>0 0 0 0 -0 0</pose>
        <scale>1 1 1</scale>
        <link name='link'>
          <pose>0 0 0 0 -0 0</pose>
          <velocity>0 0 0 0 -0 0</velocity>
          <acceleration>0 0 0 0 -0 0</acceleration>
          <wrench>0 0 0 0 -0 0</wrench>
        </link>
      </model>
      <model name='iris_demo'>
        <pose>13.2237 -48.4054 -1.9e-05 -0.000395 0 0</pose>
        <scale>1 1 1</scale>
        <link name='cam_link'>
          <pose>13.2237 -48.4054 -1.9e-05 -0.000395 0 0</pose>
          <velocity>1e-06 0 3e-06 -6.7e-05 -1e-06 1e-06</velocity>
          <acceleration>0.002207 1e-06 0 -2e-06 -0.001905 0.002435</acceleration>
          <wrench>2.2e-05 0 0 0 -0 0</wrench>
        </link>
        <link name='iris::base_link'>
          <pose>13.2237 -48.4053 0.194904 -0.000395 0 0</pose>
          <velocity>0 1.3e-05 3e-06 -6.7e-05 2e-06 0</velocity>
          <acceleration>0.000831 1e-06 0 -5e-06 0.004232 5e-06</acceleration>
          <wrench>0.001663 2e-06 0 0 -0 0</wrench>
        </link>
        <link name='iris::iris/ground_truth/odometry_sensorgt_link'>
          <pose>13.2237 -48.4053 0.194904 -0.000395 0 0</pose>
          <velocity>1e-06 1.3e-05 3e-06 -6.7e-05 -1e-06 3.9e-05</velocity>
          <acceleration>0.001231 1e-06 0 -2e-06 -0.001838 0.078162</acceleration>
          <wrench>0.000185 0 0 0 -0 0</wrench>
        </link>
        <link name='iris::iris/imu_link'>
          <pose>13.2237 -48.4053 0.194904 -0.000395 0 0</pose>
          <velocity>1e-06 1.3e-05 3e-06 -6.7e-05 -1e-06 3.9e-05</velocity>
          <acceleration>0.00122 1e-06 0 -2e-06 -0.00184 0.078197</acceleration>
          <wrench>0.000183 0 0 0 -0 0</wrench>
        </link>
        <link name='iris::rotor_0'>
          <pose>13.3537 -48.6253 0.217991 -0.000395 0 0</pose>
          <velocity>1e-06 1.5e-05 1.8e-05 -6.7e-05 -1e-06 0</velocity>
          <acceleration>0.001712 0.000325 0.000244 -2e-06 -0.001871 3.5e-05</acceleration>
          <wrench>4.3e-05 8e-06 6e-06 0 -0 0</wrench>
        </link>
        <link name='iris::rotor_1'>
          <pose>13.0937 -48.2053 0.217825 -0.000395 0 0</pose>
          <velocity>0 1.4e-05 -1.1e-05 -6.7e-05 -1e-06 0</velocity>
          <acceleration>0.000679 -0.000314 -0.000246 -9e-06 -0.001881 3.4e-05</acceleration>
          <wrench>1.7e-05 -8e-06 -6e-06 0 -0 0</wrench>
        </link>
        <link name='iris::rotor_2'>
          <pose>13.3537 -48.1853 0.217817 -0.000395 0 0</pose>
          <velocity>0 1.5e-05 -1.2e-05 -6.7e-05 -1e-06 0</velocity>
          <acceleration>0.000623 0.000321 0.000242 -1.7e-05 -0.001888 3.5e-05</acceleration>
          <wrench>1.6e-05 8e-06 6e-06 0 -0 0</wrench>
        </link>
        <link name='iris::rotor_3'>
          <pose>13.0937 -48.6053 0.217983 -0.000395 0 0</pose>
          <velocity>1e-06 1.4e-05 1.6e-05 -6.7e-05 -1e-06 0</velocity>
          <acceleration>0.001658 -0.000323 -0.000245 -7e-06 -0.001896 3.5e-05</acceleration>
          <wrench>4.1e-05 -8e-06 -6e-06 0 -0 0</wrench>
        </link>
      </model>
      <model name='su_alanı'>
        <pose>60.8323 -22.9987 -0.101596 0 -0 0</pose>
        <scale>1 1 1</scale>
        <link name='link'>
          <pose>60.8323 -22.9987 -0.101596 0 -0 0</pose>
          <velocity>0 0 0 0 -0 0</velocity>
          <acceleration>0 0 0 0 -0 0</acceleration>
          <wrench>0 0 0 0 -0 0</wrench>
        </link>
      </model>
      <model name='su_alanı_0'>
        <pose>9.49071 48.7968 -0.787891 0 -0 0</pose>
        <scale>1 1 1</scale>
        <link name='link'>
          <pose>9.49071 48.7968 -0.787891 0 -0 0</pose>
          <velocity>0 0 0 0 -0 0</velocity>
          <acceleration>0 0 0 0 -0 0</acceleration>
          <wrench>0 0 0 0 -0 0</wrench>
        </link>
      </model>
      <light name='sun'>
        <pose>1865.5 2039.39 10 0 -0 0</pose>
      </light>
    </state>
    <model name='ground_plane'>
      <static>1</static>
      <link name='link'>
        <collision name='collision'>
          <geometry>
            <plane>
              <normal>0 0 1</normal>
              <size>50000 50000</size>
            </plane>
          </geometry>
          <surface>
            <friction>
              <ode>
                <mu>1</mu>
                <mu2>1</mu2>
              </ode>
              <torsional>
                <ode/>
              </torsional>
            </friction>
            <contact>
              <ode/>
            </contact>
            <bounce/>
          </surface>
          <max_contacts>10</max_contacts>
        </collision>
        <visual name='grass'>
          <pose>0 0 -0.1 0 -0 0</pose>
          <cast_shadows>0</cast_shadows>
          <geometry>
            <plane>
              <normal>0 0 1</normal>
              <size>10000 10000</size>
            </plane>
          </geometry>
          <material>
            <script>
              <uri>file://media/materials/scripts/gazebo.material</uri>
              <name>Gazebo/Grass</name>
            </script>
          </material>
        </visual>
        <self_collide>0</self_collide>
        <enable_wind>0</enable_wind>
        <kinematic>1</kinematic>
      </link>
    </model>
    <light name='sun' type='directional'>
      <cast_shadows>1</cast_shadows>
      <pose>1865.5 2039.39 10 0 -0 0</pose>
      <diffuse>0.8 0.8 0.8 1</diffuse>
      <specular>0.2 0.2 0.2 1</specular>
      <attenuation>
        <range>1000</range>
        <constant>0.9</constant>
        <linear>0.01</linear>
        <quadratic>0.001</quadratic>
      </attenuation>
      <direction>-0.5 0.1 -0.9</direction>
      <spot>
        <inner_angle>0</inner_angle>
        <outer_angle>0</outer_angle>
        <falloff>0</falloff>
      </spot>
    </light>
    <model name='alan'>
      <pose>11.5446 -0.896078 1 0 -0 0</pose>
      <static>1</static>
      <link name='link'>
        <visual name='visual'>
          <geometry>
            <mesh>
              <scale>1 1 1</scale>
              <uri>model://alan/meshes/alan_uiha.stl</uri>
            </mesh>
          </geometry>
          <material>
            <script>
              <name>Gazebo/Black</name>
              <uri>__default__</uri>
            </script>
          </material>
        </visual>
        <self_collide>0</self_collide>
        <enable_wind>0</enable_wind>
        <kinematic>0</kinematic>
      </link>
    </model>
    <model name='daire'>
      <pose>9.38504 48.1478 1 0 -0 0</pose>
      <static>1</static>
      <link name='link'>
        <visual name='visual'>
          <geometry>
            <mesh>
              <scale>1 1 1e-06</scale>
              <uri>model://daire/meshes/daire_2x2.stl</uri>
            </mesh>
          </geometry>
          <material>
            <script>
              <name>Gazebo/Red</name>
              <uri>__default__</uri>
            </script>
          </material>
        </visual>
        <self_collide>0</self_collide>
        <enable_wind>0</enable_wind>
        <kinematic>0</kinematic>
      </link>
    </model>
    <model name='su_alanı'>
      <pose>60.8323 -22.9987 1 0 -0 0</pose>
      <static>1</static>
      <link name='link'>
        <visual name='visual'>
          <geometry>
            <mesh>
              <scale>1 1 1</scale>
              <uri>model://su_alanı/meshes/su_alanı.stl</uri>
            </mesh>
          </geometry>
          <material>
            <script>
              <name>Gazebo/Blue</name>
              <uri>__default__</uri>
            </script>
          </material>
        </visual>
        <self_collide>0</self_collide>
        <enable_wind>0</enable_wind>
        <kinematic>0</kinematic>
      </link>
    </model>
    <model name='su_alanı_0'>
      <pose>9.49071 47.9969 1 0 -0 0</pose>
      <static>1</static>
      <link name='link'>
        <visual name='visual'>
          <geometry>
            <mesh>
              <scale>1 1 1</scale>
              <uri>model://su_alanı/meshes/su_alanı.stl</uri>
            </mesh>
          </geometry>
          <material>
            <script>
              <name>Gazebo/Blue</name>
              <uri>__default__</uri>
            </script>
          </material>
        </visual>
        <self_collide>0</self_collide>
        <enable_wind>0</enable_wind>
        <kinematic>0</kinematic>
      </link>
    </model>
    <model name='iris_demo'>
      <frame name='iris::__model__' attached_to='iris::base_link'>
        <pose relative_to='__model__'>0 0 0.194923 0 -0 0</pose>
      </frame>
      <link name='iris::base_link'>
        <enable_wind>1</enable_wind>
        <velocity_decay>
          <linear>0</linear>
          <angular>0</angular>
        </velocity_decay>
        <inertial>
          <pose>0 0 0 0 -0 0</pose>
          <mass>2</mass>
          <inertia>
            <ixx>0.008</ixx>
            <ixy>0</ixy>
            <ixz>0</ixz>
            <iyy>0.015</iyy>
            <iyz>0</iyz>
            <izz>0.017</izz>
          </inertia>
        </inertial>
        <collision name='base_link_collision'>
          <pose>0 0 -0.08 0 -0 0</pose>
          <geometry>
            <box>
              <size>0.47 0.47 0.23</size>
            </box>
          </geometry>
          <surface>
            <contact>
              <ode>
                <max_vel>100</max_vel>
                <min_depth>0.001</min_depth>
              </ode>
            </contact>
            <friction>
              <ode>
                <mu>100000</mu>
                <mu2>100000</mu2>
              </ode>
              <torsional>
                <ode/>
              </torsional>
            </friction>
            <bounce/>
          </surface>
          <max_contacts>10</max_contacts>
        </collision>
        <visual name='base_link_visual'>
          <geometry>
            <mesh>
              <uri>model://iris_with_standoffs/meshes/iris.dae</uri>
            </mesh>
          </geometry>
          <material>
            <script>
              <name>Gazebo/DarkGrey</name>
              <uri>__default__</uri>
            </script>
          </material>
        </visual>
        <visual name='front_left_leg_visual'>
          <pose>0.123 0.22 -0.11 0 -0 0</pose>
          <geometry>
            <cylinder>
              <radius>0.005</radius>
              <length>0.17</length>
            </cylinder>
          </geometry>
          <material>
            <script>
              <name>Gazebo/FlatBlack</name>
              <uri>file://media/materials/scripts/gazebo.material</uri>
            </script>
          </material>
        </visual>
        <visual name='front_right_leg_visual'>
          <pose>0.123 -0.22 -0.11 0 -0 0</pose>
          <geometry>
            <cylinder>
              <radius>0.005</radius>
              <length>0.17</length>
            </cylinder>
          </geometry>
          <material>
            <script>
              <name>Gazebo/FlatBlack</name>
              <uri>file://media/materials/scripts/gazebo.material</uri>
            </script>
          </material>
        </visual>
        <visual name='rear_left_leg_visual'>
          <pose>-0.14 0.21 -0.11 0 -0 0</pose>
          <geometry>
            <cylinder>
              <radius>0.005</radius>
              <length>0.17</length>
            </cylinder>
          </geometry>
          <material>
            <script>
              <name>Gazebo/FlatBlack</name>
              <uri>file://media/materials/scripts/gazebo.material</uri>
            </script>
          </material>
        </visual>
        <visual name='rear_right_leg_visual'>
          <pose>-0.14 -0.21 -0.11 0 -0 0</pose>
          <geometry>
            <cylinder>
              <radius>0.005</radius>
              <length>0.17</length>
            </cylinder>
          </geometry>
          <material>
            <script>
              <name>Gazebo/FlatBlack</name>
              <uri>file://media/materials/scripts/gazebo.material</uri>
            </script>
          </material>
        </visual>
        <pose relative_to='iris::__model__'>0 0 0 0 -0 0</pose>
        <self_collide>0</self_collide>
        <kinematic>0</kinematic>
        <wind>10 10 0</wind>
      </link>
      <link name='iris::iris/ground_truth/odometry_sensorgt_link'>
        <pose relative_to='iris::__model__'>0 0 0 0 -0 0</pose>
        <inertial>
          <pose>0 0 0 0 -0 0</pose>
          <mass>0.15</mass>
          <inertia>
            <ixx>0.0001</ixx>
            <ixy>0</ixy>
            <ixz>0</ixz>
            <iyy>0.0002</iyy>
            <iyz>0</iyz>
            <izz>0.0002</izz>
          </inertia>
        </inertial>
        <self_collide>0</self_collide>
        <enable_wind>0</enable_wind>
        <kinematic>0</kinematic>
      </link>
      <joint name='iris::iris/ground_truth/odometry_sensorgt_joint' type='revolute'>
        <child>iris::iris/ground_truth/odometry_sensorgt_link</child>
        <parent>iris::base_link</parent>
        <axis>
          <xyz expressed_in='iris::__model__'>0 0 1</xyz>
          <limit>
            <lower>0</lower>
            <upper>0</upper>
            <effort>0</effort>
            <velocity>0</velocity>
          </limit>
          <dynamics>
            <damping>1</damping>
            <spring_reference>0</spring_reference>
            <spring_stiffness>0</spring_stiffness>
          </dynamics>
        </axis>
        <physics>
          <ode>
            <implicit_spring_damper>1</implicit_spring_damper>
            <limit>
              <cfm>0</cfm>
              <erp>0.2</erp>
            </limit>
          </ode>
        </physics>
      </joint>
      <link name='iris::iris/imu_link'>
        <inertial>
          <pose>0 0 0 0 -0 0</pose>
          <mass>0.15</mass>
          <inertia>
            <ixx>1e-05</ixx>
            <ixy>0</ixy>
            <ixz>0</ixz>
            <iyy>2e-05</iyy>
            <iyz>0</iyz>
            <izz>2e-05</izz>
          </inertia>
        </inertial>
        <sensor name='imu_sensor' type='imu'>
          <pose>0 0 0 -3.14159 -0 0</pose>
          <always_on>1</always_on>
          <update_rate>1000</update_rate>
          <imu/>
        </sensor>
        <pose relative_to='iris::__model__'>0 0 0 0 -0 0</pose>
        <self_collide>0</self_collide>
        <enable_wind>0</enable_wind>
        <kinematic>0</kinematic>
      </link>
      <joint name='iris::iris/imu_joint' type='revolute'>
        <child>iris::iris/imu_link</child>
        <parent>iris::base_link</parent>
        <axis>
          <xyz expressed_in='iris::__model__'>0 0 1</xyz>
          <limit>
            <lower>0</lower>
            <upper>0</upper>
            <effort>0</effort>
            <velocity>0</velocity>
          </limit>
          <dynamics>
            <damping>1</damping>
            <spring_reference>0</spring_reference>
            <spring_stiffness>0</spring_stiffness>
          </dynamics>
        </axis>
        <physics>
          <ode>
            <implicit_spring_damper>1</implicit_spring_damper>
            <limit>
              <cfm>0</cfm>
              <erp>0.2</erp>
            </limit>
          </ode>
        </physics>
      </joint>
      <link name='iris::rotor_0'>
        <pose relative_to='iris::__model__'>0.13 -0.22 0.023 0 -0 0</pose>
        <inertial>
          <pose>0 0 0 0 -0 0</pose>
          <mass>0.025</mass>
          <inertia>
            <ixx>9.75e-06</ixx>
            <ixy>0</ixy>
            <ixz>0</ixz>
            <iyy>0.000166704</iyy>
            <iyz>0</iyz>
            <izz>0.000167604</izz>
          </inertia>
        </inertial>
        <collision name='rotor_0_collision'>
          <pose>0 0 0 0 -0 0</pose>
          <geometry>
            <cylinder>
              <length>0.005</length>
              <radius>0.1</radius>
            </cylinder>
          </geometry>
          <surface>
            <contact>
              <ode/>
            </contact>
            <friction>
              <ode/>
              <torsional>
                <ode/>
              </torsional>
            </friction>
            <bounce/>
          </surface>
          <max_contacts>10</max_contacts>
        </collision>
        <visual name='rotor_0_visual'>
          <pose>0 0 0 0 -0 0</pose>
          <geometry>
            <mesh>
              <scale>1 1 1</scale>
              <uri>model://iris_with_standoffs/meshes/iris_prop_ccw.dae</uri>
            </mesh>
          </geometry>
          <material>
            <script>
              <name>Gazebo/Blue</name>
              <uri>__default__</uri>
            </script>
          </material>
        </visual>
        <gravity>1</gravity>
        <velocity_decay/>
        <self_collide>0</self_collide>
        <enable_wind>0</enable_wind>
        <kinematic>0</kinematic>
      </link>
      <joint name='iris::rotor_0_joint' type='revolute'>
        <child>iris::rotor_0</child>
        <parent>iris::base_link</parent>
        <axis>
          <xyz expressed_in='iris::__model__'>0 0 1</xyz>
          <limit>
            <lower>-1e+16</lower>
            <upper>1e+16</upper>
          </limit>
          <dynamics>
            <damping>0.004</damping>
            <spring_reference>0</spring_reference>
            <spring_stiffness>0</spring_stiffness>
          </dynamics>
        </axis>
        <physics>
          <ode>
            <implicit_spring_damper>1</implicit_spring_damper>
            <limit>
              <cfm>0</cfm>
              <erp>0.2</erp>
            </limit>
          </ode>
        </physics>
      </joint>
      <link name='iris::rotor_1'>
        <pose relative_to='iris::__model__'>-0.13 0.2 0.023 0 -0 0</pose>
        <inertial>
          <pose>0 0 0 0 -0 0</pose>
          <mass>0.025</mass>
          <inertia>
            <ixx>9.75e-06</ixx>
            <ixy>0</ixy>
            <ixz>0</ixz>
            <iyy>0.000166704</iyy>
            <iyz>0</iyz>
            <izz>0.000167604</izz>
          </inertia>
        </inertial>
        <collision name='rotor_1_collision'>
          <pose>0 0 0 0 -0 0</pose>
          <geometry>
            <cylinder>
              <length>0.005</length>
              <radius>0.1</radius>
            </cylinder>
          </geometry>
          <surface>
            <contact>
              <ode/>
            </contact>
            <friction>
              <ode/>
              <torsional>
                <ode/>
              </torsional>
            </friction>
            <bounce/>
          </surface>
          <max_contacts>10</max_contacts>
        </collision>
        <visual name='rotor_1_visual'>
          <pose>0 0 0 0 -0 0</pose>
          <geometry>
            <mesh>
              <scale>1 1 1</scale>
              <uri>model://iris_with_standoffs/meshes/iris_prop_ccw.dae</uri>
            </mesh>
          </geometry>
          <material>
            <script>
              <name>Gazebo/DarkGrey</name>
              <uri>__default__</uri>
            </script>
          </material>
        </visual>
        <gravity>1</gravity>
        <velocity_decay/>
        <self_collide>0</self_collide>
        <enable_wind>0</enable_wind>
        <kinematic>0</kinematic>
      </link>
      <joint name='iris::rotor_1_joint' type='revolute'>
        <child>iris::rotor_1</child>
        <parent>iris::base_link</parent>
        <axis>
          <xyz expressed_in='iris::__model__'>0 0 1</xyz>
          <limit>
            <lower>-1e+16</lower>
            <upper>1e+16</upper>
          </limit>
          <dynamics>
            <damping>0.004</damping>
            <spring_reference>0</spring_reference>
            <spring_stiffness>0</spring_stiffness>
          </dynamics>
        </axis>
        <physics>
          <ode>
            <implicit_spring_damper>1</implicit_spring_damper>
            <limit>
              <cfm>0</cfm>
              <erp>0.2</erp>
            </limit>
          </ode>
        </physics>
      </joint>
      <link name='iris::rotor_2'>
        <pose relative_to='iris::__model__'>0.13 0.22 0.023 0 -0 0</pose>
        <inertial>
          <pose>0 0 0 0 -0 0</pose>
          <mass>0.025</mass>
          <inertia>
            <ixx>9.75e-06</ixx>
            <ixy>0</ixy>
            <ixz>0</ixz>
            <iyy>0.000166704</iyy>
            <iyz>0</iyz>
            <izz>0.000167604</izz>
          </inertia>
        </inertial>
        <collision name='rotor_2_collision'>
          <pose>0 0 0 0 -0 0</pose>
          <geometry>
            <cylinder>
              <length>0.005</length>
              <radius>0.1</radius>
            </cylinder>
          </geometry>
          <surface>
            <contact>
              <ode/>
            </contact>
            <friction>
              <ode/>
              <torsional>
                <ode/>
              </torsional>
            </friction>
            <bounce/>
          </surface>
          <max_contacts>10</max_contacts>
        </collision>
        <visual name='rotor_2_visual'>
          <pose>0 0 0 0 -0 0</pose>
          <geometry>
            <mesh>
              <scale>1 1 1</scale>
              <uri>model://iris_with_standoffs/meshes/iris_prop_cw.dae</uri>
            </mesh>
          </geometry>
          <material>
            <script>
              <name>Gazebo/Blue</name>
              <uri>__default__</uri>
            </script>
          </material>
        </visual>
        <gravity>1</gravity>
        <velocity_decay/>
        <self_collide>0</self_collide>
        <enable_wind>0</enable_wind>
        <kinematic>0</kinematic>
      </link>
      <joint name='iris::rotor_2_joint' type='revolute'>
        <child>iris::rotor_2</child>
        <parent>iris::base_link</parent>
        <axis>
          <xyz expressed_in='iris::__model__'>0 0 1</xyz>
          <limit>
            <lower>-1e+16</lower>
            <upper>1e+16</upper>
          </limit>
          <dynamics>
            <damping>0.004</damping>
            <spring_reference>0</spring_reference>
            <spring_stiffness>0</spring_stiffness>
          </dynamics>
        </axis>
        <physics>
          <ode>
            <implicit_spring_damper>1</implicit_spring_damper>
            <limit>
              <cfm>0</cfm>
              <erp>0.2</erp>
            </limit>
          </ode>
        </physics>
      </joint>
      <link name='iris::rotor_3'>
        <pose relative_to='iris::__model__'>-0.13 -0.2 0.023 0 -0 0</pose>
        <inertial>
          <pose>0 0 0 0 -0 0</pose>
          <mass>0.025</mass>
          <inertia>
            <ixx>9.75e-06</ixx>
            <ixy>0</ixy>
            <ixz>0</ixz>
            <iyy>0.000166704</iyy>
            <iyz>0</iyz>
            <izz>0.000167604</izz>
          </inertia>
        </inertial>
        <collision name='rotor_3_collision'>
          <pose>0 0 0 0 -0 0</pose>
          <geometry>
            <cylinder>
              <length>0.005</length>
              <radius>0.1</radius>
            </cylinder>
          </geometry>
          <surface>
            <contact>
              <ode/>
            </contact>
            <friction>
              <ode/>
              <torsional>
                <ode/>
              </torsional>
            </friction>
            <bounce/>
          </surface>
          <max_contacts>10</max_contacts>
        </collision>
        <visual name='rotor_3_visual'>
          <pose>0 0 0 0 -0 0</pose>
          <geometry>
            <mesh>
              <scale>1 1 1</scale>
              <uri>model://iris_with_standoffs/meshes/iris_prop_cw.dae</uri>
            </mesh>
          </geometry>
          <material>
            <script>
              <name>Gazebo/DarkGrey</name>
              <uri>__default__</uri>
            </script>
          </material>
        </visual>
        <gravity>1</gravity>
        <velocity_decay/>
        <self_collide>0</self_collide>
        <enable_wind>0</enable_wind>
        <kinematic>0</kinematic>
      </link>
      <joint name='iris::rotor_3_joint' type='revolute'>
        <child>iris::rotor_3</child>
        <parent>iris::base_link</parent>
        <axis>
          <xyz expressed_in='iris::__model__'>0 0 1</xyz>
          <limit>
            <lower>-1e+16</lower>
            <upper>1e+16</upper>
          </limit>
          <dynamics>
            <damping>0.004</damping>
            <spring_reference>0</spring_reference>
            <spring_stiffness>0</spring_stiffness>
          </dynamics>
        </axis>
        <physics>
          <ode>
            <implicit_spring_damper>1</implicit_spring_damper>
            <limit>
              <cfm>0</cfm>
              <erp>0.2</erp>
            </limit>
          </ode>
        </physics>
      </joint>
      <static>0</static>
      <link name='cam_link'>
        <pose>0 0 0 0 -0 0</pose>
        <inertial>
          <mass>0.01</mass>
          <inertia>
            <ixx>0.0001</ixx>
            <iyy>0.0001</iyy>
            <izz>0.0001</izz>
            <ixy>0</ixy>
            <ixz>0</ixz>
            <iyz>0</iyz>
          </inertia>
          <pose>0 0 0 0 -0 0</pose>
        </inertial>
        <sensor name='cam' type='camera'>
          <pose>0.07 0 0.2 0 1.31859 0</pose>
          <camera>
            <horizontal_fov>1.2</horizontal_fov>
            <image>
              <width>640</width>
              <height>480</height>
            </image>
            <clip>
              <near>0.1</near>
              <far>5000</far>
            </clip>
          </camera>
          <always_on>1</always_on>
          <update_rate>60</update_rate>
          <visualize>1</visualize>
          <plugin name='camera_controller' filename='libgazebo_ros_camera.so'>
            <always_on>1</always_on>
            <update_rate>60</update_rate>
            <cameraName>iris</cameraName>
            <imageTopicName>image_raw</imageTopicName>
            <cameraInfoTopicName>camera_info</cameraInfoTopicName>
            <frameName>camera_link</frameName>
          </plugin>
        </sensor>
        <self_collide>0</self_collide>
        <enable_wind>0</enable_wind>
        <kinematic>0</kinematic>
      </link>
      <joint name='camera_mount' type='fixed'>
        <child>cam_link</child>
        <parent>iris::base_link</parent>
        <axis>
          <xyz>0 0 1</xyz>
          <limit>
            <upper>0</upper>
            <lower>0</lower>
          </limit>
        </axis>
      </joint>
      <plugin name='rotor_0_blade_1' filename='libLiftDragPlugin.so'>
        <a0>0.3</a0>
        <alpha_stall>1.4</alpha_stall>
        <cla>4.2500</cla>
        <cda>0.10</cda>
        <cma>0.00</cma>
        <cla_stall>-0.025</cla_stall>
        <cda_stall>0.0</cda_stall>
        <cma_stall>0.0</cma_stall>
        <area>0.002</area>
        <air_density>1.2041</air_density>
        <cp>0.084 0 0</cp>
        <forward>0 1 0</forward>
        <upward>0 0 1</upward>
        <link_name>iris::rotor_0</link_name>
      </plugin>
      <plugin name='rotor_0_blade_2' filename='libLiftDragPlugin.so'>
        <a0>0.3</a0>
        <alpha_stall>1.4</alpha_stall>
        <cla>4.2500</cla>
        <cda>0.10</cda>
        <cma>0.00</cma>
        <cla_stall>-0.025</cla_stall>
        <cda_stall>0.0</cda_stall>
        <cma_stall>0.0</cma_stall>
        <area>0.002</area>
        <air_density>1.2041</air_density>
        <cp>-0.084 0 0</cp>
        <forward>0 -1 0</forward>
        <upward>0 0 1</upward>
        <link_name>iris::rotor_0</link_name>
      </plugin>
      <plugin name='rotor_1_blade_1' filename='libLiftDragPlugin.so'>
        <a0>0.3</a0>
        <alpha_stall>1.4</alpha_stall>
        <cla>4.2500</cla>
        <cda>0.10</cda>
        <cma>0.00</cma>
        <cla_stall>-0.025</cla_stall>
        <cda_stall>0.0</cda_stall>
        <cma_stall>0.0</cma_stall>
        <area>0.002</area>
        <air_density>1.2041</air_density>
        <cp>0.084 0 0</cp>
        <forward>0 1 0</forward>
        <upward>0 0 1</upward>
        <link_name>iris::rotor_1</link_name>
      </plugin>
      <plugin name='rotor_1_blade_2' filename='libLiftDragPlugin.so'>
        <a0>0.3</a0>
        <alpha_stall>1.4</alpha_stall>
        <cla>4.2500</cla>
        <cda>0.10</cda>
        <cma>0.00</cma>
        <cla_stall>-0.025</cla_stall>
        <cda_stall>0.0</cda_stall>
        <cma_stall>0.0</cma_stall>
        <area>0.002</area>
        <air_density>1.2041</air_density>
        <cp>-0.084 0 0</cp>
        <forward>0 -1 0</forward>
        <upward>0 0 1</upward>
        <link_name>iris::rotor_1</link_name>
      </plugin>
      <plugin name='rotor_2_blade_1' filename='libLiftDragPlugin.so'>
        <a0>0.3</a0>
        <alpha_stall>1.4</alpha_stall>
        <cla>4.2500</cla>
        <cda>0.10</cda>
        <cma>0.00</cma>
        <cla_stall>-0.025</cla_stall>
        <cda_stall>0.0</cda_stall>
        <cma_stall>0.0</cma_stall>
        <area>0.002</area>
        <air_density>1.2041</air_density>
        <cp>0.084 0 0</cp>
        <forward>0 -1 0</forward>
        <upward>0 0 1</upward>
        <link_name>iris::rotor_2</link_name>
      </plugin>
      <plugin name='rotor_2_blade_2' filename='libLiftDragPlugin.so'>
        <a0>0.3</a0>
        <alpha_stall>1.4</alpha_stall>
        <cla>4.2500</cla>
        <cda>0.10</cda>
        <cma>0.00</cma>
        <cla_stall>-0.025</cla_stall>
        <cda_stall>0.0</cda_stall>
        <cma_stall>0.0</cma_stall>
        <area>0.002</area>
        <air_density>1.2041</air_density>
        <cp>-0.084 0 0</cp>
        <forward>0 1 0</forward>
        <upward>0 0 1</upward>
        <link_name>iris::rotor_2</link_name>
      </plugin>
      <plugin name='rotor_3_blade_1' filename='libLiftDragPlugin.so'>
        <a0>0.3</a0>
        <alpha_stall>1.4</alpha_stall>
        <cla>4.2500</cla>
        <cda>0.10</cda>
        <cma>0.00</cma>
        <cla_stall>-0.025</cla_stall>
        <cda_stall>0.0</cda_stall>
        <cma_stall>0.0</cma_stall>
        <area>0.002</area>
        <air_density>1.2041</air_density>
        <cp>0.084 0 0</cp>
        <forward>0 -1 0</forward>
        <upward>0 0 1</upward>
        <link_name>iris::rotor_3</link_name>
      </plugin>
      <plugin name='rotor_3_blade_2' filename='libLiftDragPlugin.so'>
        <a0>0.3</a0>
        <alpha_stall>1.4</alpha_stall>
        <cla>4.2500</cla>
        <cda>0.10</cda>
        <cma>0.00</cma>
        <cla_stall>-0.025</cla_stall>
        <cda_stall>0.0</cda_stall>
        <cma_stall>0.0</cma_stall>
        <area>0.002</area>
        <air_density>1.2041</air_density>
        <cp>-0.084 0 0</cp>
        <forward>0 1 0</forward>
        <upward>0 0 1</upward>
        <link_name>iris::rotor_3</link_name>
      </plugin>
      <plugin name='arducopter_plugin' filename='libArduPilotPlugin.so'>
        <fdm_addr>127.0.0.1</fdm_addr>
        <fdm_port_in>9002</fdm_port_in>
        <fdm_port_out>9003</fdm_port_out>
        <modelXYZToAirplaneXForwardZDown>0 0 0 3.141593 0 0</modelXYZToAirplaneXForwardZDown>
        <gazeboXYZToNED>0 0 0 3.141593 0 0</gazeboXYZToNED>
        <imuName>iris_demo::iris::iris/imu_link::imu_sensor</imuName>
        <connectionTimeoutMaxCount>5</connectionTimeoutMaxCount>
        <control channel='0'>
          <type>VELOCITY</type>
          <cmd_max>2.5</cmd_max>
          <cmd_min>-2.5</cmd_min>
          <jointName>iris::rotor_0_joint</jointName>
          <multiplier>838</multiplier>
          <controlVelocitySlowdownSim>1</controlVelocitySlowdownSim>
        </control>
        <control channel='1'>
          <type>VELOCITY</type>
          <cmd_max>2.5</cmd_max>
          <cmd_min>-2.5</cmd_min>
          <jointName>iris::rotor_1_joint</jointName>
          <multiplier>838</multiplier>
          <controlVelocitySlowdownSim>1</controlVelocitySlowdownSim>
        </control>
        <control channel='2'>
          <type>VELOCITY</type>
          <cmd_max>2.5</cmd_max>
          <cmd_min>-2.5</cmd_min>
          <jointName>iris::rotor_2_joint</jointName>
          <multiplier>-838</multiplier>
          <controlVelocitySlowdownSim>1</controlVelocitySlowdownSim>
        </control>
        <control channel='3'>
          <type>VELOCITY</type>
          <cmd_max>2.5</cmd_max>
          <cmd_min>-2.5</cmd_min>
          <jointName>iris::rotor_3_joint</jointName>
          <multiplier>-838</multiplier>
          <controlVelocitySlowdownSim>1</controlVelocitySlowdownSim>
        </control>
      </plugin>
      <pose>13.6585 -48.3288 0 0 -0 0</pose>
    </model>
  </world>
</sdf>
